<?xml version="1.0" ?>
<!-- =================================================================================== -->
<!-- |    This document was autogenerated by xacro from mechROS.xacro                  | -->
<!-- |    EDITING THIS FILE BY HAND IS NOT RECOMMENDED                                 | -->
<!-- =================================================================================== -->
<robot name="mechROS" xmlns:xacro="http://www.ros.org/wiki/xacro">
  <!-- PROPERTIES & MACROS -->
  <!-- ////////////////////////////////////////////////// -->
  <!-- MATERIALS -->
  <!-- ////////////////////////////////////////////////// -->
  <material name="camera_color">
    <color rgba=".01 1 .5 1"/>
  </material>
  <!--<material name="tire_texture">-->
  <!--    <texture filename="package://robot_description/textures/rubber.jpg" />-->
  <!--</material>-->
  <!-- Import files -->
  <material name="tire_texture">
    <texture filename="file:///home/patrik/catkin_ws/src/mech_ros/robot_description/textures/rubber.jpg"/>
  </material>
  <!-- skid steering plugin -->
  <!--	<xacro:macro name="skid_steering" params="broadcastOdomTF prefix wheelSeparation wheelDiameter">-->
  <!--    <gazebo>-->
  <!--      <plugin name="skid_steer_drive_controller" filename="libgazebo_ros_skid_steer_drive.so">-->
  <!--         <robotNamespace>/mechROS</robotNamespace>-->
  <!--		    <updateRate>100.0</updateRate>-->
  <!--		    <leftFrontJoint>front_left_wheel_joint</leftFrontJoint>  -->
  <!--		    <rightFrontJoint>front_right_wheel_joint</rightFrontJoint>-->
  <!--		    <leftRearJoint>back_left_wheel_joint</leftRearJoint>-->
  <!--		    <rightRearJoint>back_right_wheel_joint</rightRearJoint>-->
  <!--		    <wheelSeparation>${wheelSeparation}</wheelSeparation>-->
  <!--		    <wheelDiameter>${wheelDiameter}</wheelDiameter>-->
  <!--		    <robotBaseFrame>${prefix}base_link</robotBaseFrame>-->
  <!--		    <torque>50</torque>-->
  <!--		    <commandTopic>control/cmd_vel</commandTopic>-->
  <!--		    <odometryTopic>control/odom</odometryTopic>-->
  <!--		    <odometryFrame>/odom</odometryFrame>-->
  <!--		    <odometryFrame>${prefix}odom</odometryFrame>-->
  <!--		    <broadcastTF>${broadcastOdomTF}</broadcastTF>-->
  <!--      </plugin>-->
  <!--    </gazebo>-->
  <!--  </xacro:macro>-->
  <!--  -->
  <!--  <xacro:macro name="omni_steering" params="prefix publish_tf">-->
  <!--		<gazebo>-->
  <!--	    <plugin name="omni_steering" filename="libgazebo_ros_planar_move.so">-->
  <!--	      <commandTopic>robotnik_base_control/cmd_vel</commandTopic>  -->
  <!--	      <odometryTopic>robotnik_base_control/odom</odometryTopic>-->
  <!--	      <odometryFrame>${prefix}odom</odometryFrame>-->
  <!--	      <odometryRate>50.0</odometryRate>-->
  <!--	      <robotBaseFrame>${prefix}base_footprint</robotBaseFrame>-->
  <!--	      <publishTF>${publish_tf}</publishTF>-->
  <!--	    </plugin>-->
  <!--	  </gazebo>-->
  <!--  </xacro:macro>-->
  <!--  <xacro:macro name="ros_force_based_move" params="publish_tf prefix">-->
  <!--	  <gazebo>-->
  <!--		 <plugin name="ros_force_based_move" filename="libgazebo_ros_force_based_move.so">-->
  <!--			 <commandTopic>robotnik_base_control/cmd_vel</commandTopic>  -->
  <!--			 <odometryTopic>robotnik_base_control/odom</odometryTopic>-->
  <!--	         <odometryFrame>${prefix}odom</odometryFrame>-->
  <!--			 <yaw_velocity_p_gain>10000.0</yaw_velocity_p_gain>-->
  <!--			 <x_velocity_p_gain>10000.0</x_velocity_p_gain>-->
  <!--			 <y_velocity_p_gain>10000.0</y_velocity_p_gain>-->
  <!--			 <robotBaseFrame>${prefix}base_footprint</robotBaseFrame>-->
  <!--			 <odometryRate>50.0</odometryRate>-->
  <!--			 <publishOdometryTf>${publish_tf}</publishOdometryTf>-->
  <!--		 </plugin>-->
  <!--	  </gazebo>-->
  <!--  </xacro:macro>-->
  <!--  <gazebo reference="base_footprint">-->
  <!--    <material>Gazebo/Green</material>-->
  <!--  </gazebo>-->
  <!-- This file unifies all sensors that can be used on simulation, defined as xacro:macros -->
  <material name="gray_color">
    <color rgba=".75 .75 .75 1"/>
  </material>
  <!-- LINKS -->
  <!-- ////////////////////////////////////////////////// -->
  <link name="mechROS_base_link">
    <visual>
      <origin rpy="1.57079632679 0 1.57079632679" xyz="0.011 -0.060276 0"/>
      <geometry>
        <!--        <mesh filename="package://robot_description/meshes/Chassis.stl"/>-->
        <mesh filename="file:///home/patrik/catkin_ws/src/mech_ros/robot_description/meshes/Chassis_10000.stl" scale="0.01 0.01 0.01"/>
        <!--	<cylinder length="0.2" radius="0.4" />-->
      </geometry>
      <material name="gray_color"/>
    </visual>
    <collision>
      <origin rpy="0 0 0" xyz="0.008 0 0.023"/>
      <geometry>
        <box size="0.242 0.11 0.085"/>
      </geometry>
    </collision>
    <!-- !!!!!!!!!!!!!!!!!!!-->
    <!--NASTAVAIT SPRAVNE INERTIAL-->
    <inertial>
      <origin xyz="0 0 0.02"/>
      <mass value="1.172"/>
      <!--	<mass value="1" />-->
      <inertia ixx="0.001568" ixy="0.0" ixz="0.0" iyy="0.003775" iyz="0.0" izz="0.00483"/>
    </inertial>
  </link>
  <gazebo reference="mechROS_base_link">
    <material>Gazebo/GreyGradientSky</material>
    <turnGravityOff>false</turnGravityOff>
  </gazebo>
  <!-- *************** -->
  <!-- Robots Elements -->
  <!-- *************** -->
  <!--WHEEL TIRE -->
  <joint name="front_right_wheel_joint" type="continuous">
    <parent link="mechROS_base_link"/>
    <child link="front_right_wheel"/>
    <origin rpy="0 0 0" xyz="0.063 -0.0735 0.018"/>
    <axis rpy="0 0 0" xyz="0 1 0"/>
    <limit effort="100" velocity="100"/>
    <joint_properties damping="0.0" friction="0.0"/>
  </joint>
  <link name="front_right_wheel">
    <visual>
      <origin rpy="1.57079632679 0 0" xyz="0 -0.003 0"/>
      <geometry>
        <mesh filename="file:///home/patrik/catkin_ws/src/mech_ros/robot_description/meshes/Wheel_hub_simplified.stl" scale="0.01 0.01 0.01"/>
        <!--	<cylinder length="${wheel_height}" radius="${wheel_radius}" />-->
      </geometry>
      <material name="tire_texture"/>
    </visual>
    <collision>
      <origin rpy="1.57079632679 0 0" xyz="0 -0.003 0"/>
      <geometry>
        <cylinder length="0.031" radius="0.05"/>
      </geometry>
    </collision>
    <inertial>
      <mass value="0.079"/>
      <origin rpy="0 0 0" xyz="0 -0.003 0"/>
      <origin xyz="0 0 0"/>
      <!--        <inertia  ixx="0.000049044" ixy = "0" ixz = "0"-->
      <!--              iyy="0.000083396" iyz = "0"-->
      <!--              izz="0.000048972" />-->
      <inertia ixx="0.00069" ixy="0" ixz="0" iyy="0.0012057" iyz="0" izz="0.00069"/>
    </inertial>
  </link>
  <!-- Transmission is important to link the joints and the controller (see summit_xl_control/config/summit_xl_control.yaml)-->
  <transmission name="front_right_wheel_joint_trans">
    <type>transmission_interface/SimpleTransmission</type>
    <joint name="front_right_wheel_joint">
      <hardwareInterface>hardware_interface/VelocityJointInterface</hardwareInterface>
    </joint>
    <actuator name="front_right_wheel_joint_motor">
      <mechanicalReduction>1</mechanicalReduction>
      <motorTorqueConstant>20</motorTorqueConstant>
    </actuator>
  </transmission>
  <gazebo reference="front_right_wheel">
    <mu1 value="1.0"/>
    <mu2 value="1.0"/>
    <kp value="10000000.0"/>
    <kd value="1.0"/>
    <fdir1 value="1 0 0"/>
    <material>Gazebo/Residential</material>
    <turnGravityOff>false</turnGravityOff>
  </gazebo>
  <!--WHEEL TIRE -->
  <joint name="front_left_wheel_joint" type="continuous">
    <parent link="mechROS_base_link"/>
    <child link="front_left_wheel"/>
    <origin rpy="0 0 0" xyz="0.063 0.0735 0.018"/>
    <axis rpy="0 0 0" xyz="0 1 0"/>
    <limit effort="100" velocity="100"/>
    <joint_properties damping="0.0" friction="0.0"/>
  </joint>
  <link name="front_left_wheel">
    <visual>
      <origin rpy="-1.57079632679 0 0" xyz="0 0.003 0"/>
      <geometry>
        <mesh filename="file:///home/patrik/catkin_ws/src/mech_ros/robot_description/meshes/Wheel_hub_simplified.stl" scale="0.01 0.01 0.01"/>
        <!--	<cylinder length="${wheel_height}" radius="${wheel_radius}" />-->
      </geometry>
      <material name="tire_texture"/>
    </visual>
    <collision>
      <origin rpy="1.57079632679 0 0" xyz="0 0.003 0"/>
      <geometry>
        <cylinder length="0.031" radius="0.05"/>
      </geometry>
    </collision>
    <inertial>
      <mass value="0.079"/>
      <origin rpy="0 0 0" xyz="0 0.003 0"/>
      <origin xyz="0 0 0"/>
      <!--        <inertia  ixx="0.000049044" ixy = "0" ixz = "0"-->
      <!--              iyy="0.000083396" iyz = "0"-->
      <!--              izz="0.000048972" />-->
      <inertia ixx="0.00069" ixy="0" ixz="0" iyy="0.0012057" iyz="0" izz="0.00069"/>
    </inertial>
  </link>
  <!-- Transmission is important to link the joints and the controller (see summit_xl_control/config/summit_xl_control.yaml)-->
  <transmission name="front_left_wheel_joint_trans">
    <type>transmission_interface/SimpleTransmission</type>
    <joint name="front_left_wheel_joint">
      <hardwareInterface>hardware_interface/VelocityJointInterface</hardwareInterface>
    </joint>
    <actuator name="front_left_wheel_joint_motor">
      <mechanicalReduction>1</mechanicalReduction>
      <motorTorqueConstant>20</motorTorqueConstant>
    </actuator>
  </transmission>
  <gazebo reference="front_left_wheel">
    <mu1 value="1.0"/>
    <mu2 value="1.0"/>
    <kp value="10000000.0"/>
    <kd value="1.0"/>
    <fdir1 value="1 0 0"/>
    <material>Gazebo/Residential</material>
    <turnGravityOff>false</turnGravityOff>
  </gazebo>
  <!--WHEEL TIRE -->
  <joint name="back_left_wheel_joint" type="continuous">
    <parent link="mechROS_base_link"/>
    <child link="back_left_wheel"/>
    <origin rpy="0 0 0" xyz="-0.063 0.0735 0.018"/>
    <axis rpy="0 0 0" xyz="0 1 0"/>
    <limit effort="100" velocity="100"/>
    <joint_properties damping="0.0" friction="0.0"/>
  </joint>
  <link name="back_left_wheel">
    <visual>
      <origin rpy="-1.57079632679 0 0" xyz="0 0.003 0"/>
      <geometry>
        <mesh filename="file:///home/patrik/catkin_ws/src/mech_ros/robot_description/meshes/Wheel_hub_simplified.stl" scale="0.01 0.01 0.01"/>
        <!--	<cylinder length="${wheel_height}" radius="${wheel_radius}" />-->
      </geometry>
      <material name="tire_texture"/>
    </visual>
    <collision>
      <origin rpy="1.57079632679 0 0" xyz="0 0.003 0"/>
      <geometry>
        <cylinder length="0.031" radius="0.05"/>
      </geometry>
    </collision>
    <inertial>
      <mass value="0.079"/>
      <origin rpy="0 0 0" xyz="0 0.003 0"/>
      <origin xyz="0 0 0"/>
      <!--        <inertia  ixx="0.000049044" ixy = "0" ixz = "0"-->
      <!--              iyy="0.000083396" iyz = "0"-->
      <!--              izz="0.000048972" />-->
      <inertia ixx="0.00069" ixy="0" ixz="0" iyy="0.0012057" iyz="0" izz="0.00069"/>
    </inertial>
  </link>
  <!-- Transmission is important to link the joints and the controller (see summit_xl_control/config/summit_xl_control.yaml)-->
  <transmission name="back_left_wheel_joint_trans">
    <type>transmission_interface/SimpleTransmission</type>
    <joint name="back_left_wheel_joint">
      <hardwareInterface>hardware_interface/VelocityJointInterface</hardwareInterface>
    </joint>
    <actuator name="back_left_wheel_joint_motor">
      <mechanicalReduction>1</mechanicalReduction>
      <motorTorqueConstant>20</motorTorqueConstant>
    </actuator>
  </transmission>
  <gazebo reference="back_left_wheel">
    <mu1 value="1.0"/>
    <mu2 value="1.0"/>
    <kp value="10000000.0"/>
    <kd value="1.0"/>
    <fdir1 value="1 0 0"/>
    <material>Gazebo/Residential</material>
    <turnGravityOff>false</turnGravityOff>
  </gazebo>
  <!--WHEEL TIRE -->
  <joint name="back_right_wheel_joint" type="continuous">
    <parent link="mechROS_base_link"/>
    <child link="back_right_wheel"/>
    <origin rpy="0 0 0" xyz="-0.063 -0.0735 0.018"/>
    <axis rpy="0 0 0" xyz="0 1 0"/>
    <limit effort="100" velocity="100"/>
    <joint_properties damping="0.0" friction="0.0"/>
  </joint>
  <link name="back_right_wheel">
    <visual>
      <origin rpy="1.57079632679 0 0" xyz="0 -0.003 0"/>
      <geometry>
        <mesh filename="file:///home/patrik/catkin_ws/src/mech_ros/robot_description/meshes/Wheel_hub_simplified.stl" scale="0.01 0.01 0.01"/>
        <!--	<cylinder length="${wheel_height}" radius="${wheel_radius}" />-->
      </geometry>
      <material name="tire_texture"/>
    </visual>
    <collision>
      <origin rpy="1.57079632679 0 0" xyz="0 -0.003 0"/>
      <geometry>
        <cylinder length="0.031" radius="0.05"/>
      </geometry>
    </collision>
    <inertial>
      <mass value="0.079"/>
      <origin rpy="0 0 0" xyz="0 -0.003 0"/>
      <origin xyz="0 0 0"/>
      <!--        <inertia  ixx="0.000049044" ixy = "0" ixz = "0"-->
      <!--              iyy="0.000083396" iyz = "0"-->
      <!--              izz="0.000048972" />-->
      <inertia ixx="0.00069" ixy="0" ixz="0" iyy="0.0012057" iyz="0" izz="0.00069"/>
    </inertial>
  </link>
  <!-- Transmission is important to link the joints and the controller (see summit_xl_control/config/summit_xl_control.yaml)-->
  <transmission name="back_right_wheel_joint_trans">
    <type>transmission_interface/SimpleTransmission</type>
    <joint name="back_right_wheel_joint">
      <hardwareInterface>hardware_interface/VelocityJointInterface</hardwareInterface>
    </joint>
    <actuator name="back_right_wheel_joint_motor">
      <mechanicalReduction>1</mechanicalReduction>
      <motorTorqueConstant>20</motorTorqueConstant>
    </actuator>
  </transmission>
  <gazebo reference="back_right_wheel">
    <mu1 value="1.0"/>
    <mu2 value="1.0"/>
    <kp value="10000000.0"/>
    <kd value="1.0"/>
    <fdir1 value="1 0 0"/>
    <material>Gazebo/Residential</material>
    <turnGravityOff>false</turnGravityOff>
  </gazebo>
  <joint name="imu_joint" type="fixed">
    <axis xyz="1 0 0"/>
    <origin rpy="0 0 0" xyz="0 0.0 0.055"/>
    <parent link="mechROS_base_link"/>
    <child link="imu_link"/>
  </joint>
  <link name="imu_link">
    <inertial>
      <mass value="0.001"/>
      <origin rpy="0 0 0" xyz="0 0 0"/>
      <inertia ixx="0.0001" ixy="0" ixz="0" iyy="0.000001" iyz="0" izz="0.0001"/>
    </inertial>
    <visual>
      <origin rpy="0 0 0" xyz="0 0 0"/>
      <geometry>
        <box size="0.001 0.001 0.001"/>
      </geometry>
    </visual>
    <collision>
      <origin rpy="0 0 0" xyz="0 0 0"/>
      <geometry>
        <box size=".001 .001 .001"/>
      </geometry>
    </collision>
  </link>
  <gazebo>
    <plugin filename="libhector_gazebo_ros_imu.so" name="imu_controller">
      <alwaysOn>true</alwaysOn>
      <topicName>imu/data_raw</topicName>
      <serviceName>imu/service_raw</serviceName>
      <bodyName>imu_link</bodyName>
      <frameId>imu_link</frameId>
      <updateRate>50.0</updateRate>
      <gaussianNoise>0.01</gaussianNoise>
      <!-- orientation parameters -->
      <yawOffset>0.0</yawOffset>
      <!--<yawOffset>0.0</yawOffset>-->
      <yawDrift>0.005</yawDrift>
      <!--<yawDrift>0.0</yawDrift>-->
      <yawGaussianNoise>0.005</yawGaussianNoise>
      <!--<yawGaussianNoise>0.0004</yawGaussianNoise>-->
      <!-- angular velocities parameters -->
      <rateOffset>0.0 0.0 0.0</rateOffset>
      <rateDrift>0.005 0.005 0.005</rateDrift>
      <!--<rateDrift>0.0 0.0 0.0</rateDrift>-->
      <rateGaussianNoise>0.005 0.005 0.005</rateGaussianNoise>
      <!--<rateGaussianNoise>0.004 0.004 0.004</rateGaussianNoise>-->
      <!-- linear accelerations parameters -->
      <accelOffset>0.0 0.0 0.0</accelOffset>
      <accelDrift>0.005 0.005 0.005</accelDrift>
      <!--<accelDrift>0.0 0.0 0.0</accelDrift>-->
      <accelGaussianNoise>0.05 0.05 0.05</accelGaussianNoise>
      <!--<accelGaussianNoise>0.004 0.004 0.004</accelGaussianNoise>-->
    </plugin>
  </gazebo>
  <joint name="imu_magnetic_joint" type="fixed">
    <axis xyz="1 0 0"/>
    <origin rpy="0 -1.5707963267 1.5707963267" xyz="0 0 0"/>
    <parent link="imu_link"/>
    <child link="imu_magnetic_link"/>
  </joint>
  <link name="imu_magnetic_link">
    <inertial>
      <mass value="0.001"/>
      <origin rpy="0 0 0" xyz="0 0 0"/>
      <inertia ixx="0.0001" ixy="0" ixz="0" iyy="0.000001" iyz="0" izz="0.0001"/>
    </inertial>
    <visual>
      <origin rpy="0 0 0" xyz="0 0 0"/>
      <geometry>
        <box size="0.001 0.001 0.001"/>
      </geometry>
    </visual>
    <collision>
      <origin rpy="0 0 0" xyz="0 0 0"/>
      <geometry>
        <box size=".001 .001 .001"/>
      </geometry>
    </collision>
  </link>
  <gazebo>
    <plugin filename="libhector_gazebo_ros_magnetic.so" name="magnetic_controller">
      <alwaysOn>true</alwaysOn>
      <topicName>imu/mag</topicName>
      <serviceName>imu/mag/service</serviceName>
      <bodyName>imu_magnetic_link</bodyName>
      <frameId>imu_magnetic_link</frameId>
      <updateRate>50.0</updateRate>
      <gaussianNoise>0.005 0.005 0.005</gaussianNoise>
      <!-- orientation parameters -->
      <offset>0.0 0.0 0.0</offset>
      <!--           <offset>0.0 0.0 0.0</offset>-->
      <magnitude>1.0</magnitude>
      <!--		<magnitude>1.0</magnitude>-->
      <!-- <referenceHeading>1.5707963267</referenceHeading> -->
      <referenceHeading>0.0</referenceHeading>
      <declination>0.0</declination>
      <!--		<declination>0.0</declination>-->
      <inclination>60.0</inclination>
      <!--		<inclination>0.0</inclination>-->
      <drift>0.005 0.005 0.005</drift>
      <!--		<drift>0.001 0.001 0.001</drift>-->
      <driftFrequency>0.0001 0.0001 0.0001</driftFrequency>
      <!--		<driftFrequency>0.1 0.1 0.1</driftFrequency>-->
    </plugin>
  </gazebo>
  <!-- camera body, with origin at bottom screw mount -->
  <joint name="front_camera_joint" type="fixed">
    <origin rpy="0 0 0" xyz="0.088 0 0.0204"/>
    <parent link="mechROS_base_link"/>
    <child link="front_camera_link"/>
  </joint>
  <link name="front_camera_link">
    <visual>
      <!--     <origin xyz="0 0 0" rpy="0 ${PI/2} 0"/>-->
      <origin rpy="0 -1.57079632679 3.14159265359" xyz="0 0 0"/>
      <geometry>
        <mesh filename="file:///home/patrik/catkin_ws/src/mech_ros/robot_description/meshes/Camera_2000_simplified.stl" scale="0.01 0.01 0.01"/>
      </geometry>
      <material name="camera_color"/>
    </visual>
    <collision>
      <origin rpy="0 0 0" xyz="-0.0125 0.0 0.0"/>
      <geometry>
        <box size="0.025 0.1 0.025"/>
      </geometry>
    </collision>
    <inertial>
      <!-- The following are not reliable values, and should not be used for modeling -->
      <mass value="0.01064"/>
      <origin xyz="0 0 0"/>
      <inertia ixx="0.00003881243" ixy="0.0" ixz="0.0" iyy="0.00000498940" iyz="0.0" izz="0.00003879257"/>
    </inertial>
  </link>
  <!-- camera -->
  <gazebo reference="front_camera_link">
    <sensor name="camera1" type="camera">
      <update_rate>30.0</update_rate>
      <camera name="head">
        <horizontal_fov>1.3962634</horizontal_fov>
        <image>
          <width>1280</width>
          <height>720</height>
          <format>R8G8B8</format>
        </image>
        <clip>
          <near>0.02</near>
          <far>300</far>
        </clip>
        <noise>
          <type>gaussian</type>
          <!-- Noise is sampled independently per pixel on each frame.
               That pixel's noise value is added to each of its color
               channels, which at that point lie in the range [0,1]. -->
          <mean>0.0</mean>
          <stddev>0.007</stddev>
        </noise>
      </camera>
      <plugin filename="libgazebo_ros_camera.so" name="camera_controller">
        <alwaysOn>true</alwaysOn>
        <updateRate>0.0</updateRate>
        <cameraName>pi_camera</cameraName>
        <imageTopicName>image_raw</imageTopicName>
        <cameraInfoTopicName>camera_info</cameraInfoTopicName>
        <frameName>front_camera_link</frameName>
        <hackBaseline>0.07</hackBaseline>
        <distortionK1>0.0</distortionK1>
        <distortionK2>0.0</distortionK2>
        <distortionK3>0.0</distortionK3>
        <distortionT1>0.0</distortionT1>
        <distortionT2>0.0</distortionT2>
      </plugin>
    </sensor>
    <material>Gazebo/Grass</material>
  </gazebo>
  <link name="laser_link">
	</link>
  <joint name="laser_joint" type="fixed">
    <parent link="mechROS_base_link"/>
    <child link="laser_link"/>
    <origin rpy="0 0 0" xyz="0.00 0 0.0804"/>
  </joint>
  <joint name="laser_base_joint" type="fixed">
    <origin rpy="0 0 0" xyz="0.00 0 -0.05"/>
    <parent link="laser_link"/>
    <child link="laser_base_link"/>
  </joint>
  <link name="laser_base_link">
    <collision>
      <origin rpy="0 0 0" xyz="0 0 0.0"/>
      <geometry>
        <box size="0.010 0.010 0.010"/>
      </geometry>
    </collision>
    <visual>
      <origin rpy="0 0 0" xyz="0 0 0.0"/>
      <geometry>
        <mesh filename="file:///home/patrik/catkin_ws/src/mech_ros/robot_description/sensors/meshes/hokuyo_ust_10lx.dae"/>
      </geometry>
    </visual>
    <inertial>
      <mass value="1e-5"/>
      <origin rpy="0 0 0" xyz="0 0 0"/>
      <inertia ixx="1e-6" ixy="0" ixz="0" iyy="1e-6" iyz="0" izz="1e-6"/>
    </inertial>
  </link>
  <gazebo reference="laser_link">
    <sensor name="laser_sensor" type="gpu_ray">
      <pose>0 0 0 0 0 0</pose>
      <visualize>false</visualize>
      <update_rate>40</update_rate>
      <ray>
        <scan>
          <horizontal>
            <samples>1081</samples>
            <resolution>1</resolution>
            <min_angle>-2.3562</min_angle>
            <max_angle>2.3562</max_angle>
          </horizontal>
        </scan>
        <range>
          <min>0.06</min>
          <max>10.0</max>
          <!-- resolution>0.004363323</resolution -->
          <resolution>0.004359297</resolution>
          <!-- resolution>0.001</resolution -->
        </range>
        <noise>
          <type>gaussian</type>
          <mean>0.0</mean>
          <stddev>0.01</stddev>
        </noise>
      </ray>
      <plugin filename="libgazebo_ros_gpu_laser.so" name="laser_controller">
        <topicName>front_laser/scan</topicName>
        <frameName>/laser_link</frameName>
      </plugin>
    </sensor>
  </gazebo>
   --&gt;




  <gazebo>
    <plugin filename="libgazebo_ros_control.so" name="ros_control">
      <robotNamespace>/mechROS</robotNamespace>
      <!--		<robotParam>robot_description</robotParam>-->
      <controlPeriod>0.001</controlPeriod>
      <robotSimType>gazebo_ros_control/DefaultRobotHWSim</robotSimType>
    </plugin>
  </gazebo>
  <!--<xacro:skid_steering broadcastOdomTF="true" prefix="$(arg prefix)" wheelSeparation="$(arg wheel_offset_y)" wheelDiameter="0.01"/>-->
  <!--<link name="camera">-->
  <!--    <visual>-->
  <!--	<origin xyz="0 0 0" rpy="0 ${-PI/2} ${PI}"/>-->
  <!--     <geometry>-->
  <!--        <mesh filename="file:///home/patrik/catkin_ws/src/mech_ros/robot_description/meshes/Camera.stl" scale="${Scale}"/>-->
  <!--      </geometry>-->
  <!--     <material name="camera_color"/>-->
  <!--    </visual>-->
  <!--    <collision>-->
  <!--      <origin xyz="0 0 0" rpy="0 0 0"/>-->
  <!--      <geometry>-->
  <!--        <box size="0.01 0.2 0.05"/>-->
  <!--      </geometry>-->
  <!--    </collision>-->
  <!--</link>-->
  <!-- JOINTS -->
  <!-- ////////////////////////////////////////////////// -->
  <!--<xacro:Joint_f name="Body" parent="base_link" child="camera" xyz="0.088 0 0.0204" rpy="0 0 0"/>-->
</robot>

